<?xml version="1.0" encoding="UTF-8"?>
<sdf version='1.9'>
  <model name='homebrew_base'>
    <pose>0 0 2 0 0 0</pose>
    <self_collide>false</self_collide>
    <static>false</static>
    <link name="base_link">
      <self_collide>false</self_collide>
      <gravity>true</gravity>
      <velocity_decay />

      <inertial> <!--base link inertial is fine-->
        <!--<pose>0.00354550592318617 0.000240772299052172 -0.0160698216491228 0 0 0</pose>-->
        <mass>2.27304650076778</mass>
        <inertia>
          <ixx>0.0042284876572578</ixx>
          <ixy>0</ixy>
          <ixz>0</ixz>
          <iyy>0.00572258822097371</iyy>
          <iyz>0</iyz>
          <izz>0.00831273635864134</izz>
        </inertia>
      </inertial>

      <visual name="base_link_visual">
        <material>
          <ambient>0.1 0.1 0.1 1</ambient>
          <diffuse>0.1 0.1 0.2 1</diffuse>
          <specular>0 0 0 0</specular>
          <emissive>0 0 0 1</emissive>
        </material>
        <pose>0 0 0 0 0 0</pose>
        <geometry>
          <mesh>
            <scale>1 1 1</scale>
            <uri>model://homebrew_base/meshes/base_link.STL</uri>
          </mesh>
        </geometry>
      </visual>

      <!--<collision name="base_link_collision_0">
        <pose>0 0 .007 0 0 0</pose>
        <geometry>
          <box>
            <size>0.35355339059327373 0.35355339059327373 0.05</size>
          </box>
        </geometry>
        <surface>
          <contact>
            <ode>
              <min_depth>0.001</min_depth>
              <max_vel>0</max_vel>
            </ode>
          </contact>
          <friction>
            <ode/>
          </friction>
        </surface>
      </collision>
      <collision name="base_link_collision_1">
        <pose>0 -0.098 -.123 -0.35 0 0</pose>
        <geometry>
          <box>
            <size>0.015 0.015 0.21</size>
          </box>
        </geometry>
        <surface>
          <contact>
            <ode>
              <min_depth>0.001</min_depth>
              <max_vel>0</max_vel>
            </ode>
          </contact>
          <friction>
            <ode/>
          </friction>
        </surface>
      </collision>
      <collision name="base_link_collision_2">
        <pose>0 0.098 -.123 0.35 0 0</pose>
        <geometry>
          <box>
            <size>0.015 0.015 0.21</size>
          </box>
        </geometry>
        <surface>
          <contact>
            <ode>
              <min_depth>0.001</min_depth>
              <max_vel>0</max_vel>
            </ode>
          </contact>
          <friction>
            <ode/>
          </friction>
        </surface>
      </collision>
      <collision name="base_link_collision_3">
        <pose>0 -0.132 -.2195 0 0 0</pose>
        <geometry>
          <box>
            <size>0.25 0.015 0.015</size>
          </box>
        </geometry>
        <surface>
          <contact>
            <ode>
              <min_depth>0.001</min_depth>
              <max_vel>0</max_vel>
            </ode>
          </contact>
          <friction>
            <ode/>
          </friction>
        </surface>
      </collision>
      <collision name="base_link_collision_4">
        <pose>0 0.132 -.2195 0 0 0</pose>
        <geometry>
          <box>
            <size>0.25 0.015 0.015</size>
          </box>
        </geometry>
        <surface>
          <contact>
            <ode>
              <min_depth>0.001</min_depth>
              <max_vel>0</max_vel>
            </ode>
          </contact>
          <friction>
            <ode/>
          </friction>
        </surface>
      </collision>-->

      <collision name="base_link_collision">
        <pose>0 0 0 0 0 0</pose>
        <geometry>
          <mesh>
            <uri>model://homebrew_base/meshes/base_link.STL</uri>
          </mesh>
        </geometry>
        <surface>
          <contact>
            <ode>
              <min_depth>0.001</min_depth>
              <max_vel>0</max_vel>
            </ode>
          </contact>
          <friction>
            <ode />
          </friction>
        </surface>
      </collision>

      <!--<sensor name="imu_sensor" type="imu">
        <always_on>1</always_on>
        <update_rate>250</update_rate>
        <imu>
          <angular_velocity>
            <x><noise type="gaussian"><mean>0</mean><stddev>0.0008726646</stddev></noise></x>
            <y><noise type="gaussian"><mean>0</mean><stddev>0.0008726646</stddev></noise></y>
            <z><noise type="gaussian"><mean>0</mean><stddev>0.0008726646</stddev></noise></z>
          </angular_velocity>
          <linear_acceleration>
            <x><noise type="gaussian"><mean>0</mean><stddev>0.00637</stddev></noise></x>
            <y><noise type="gaussian"><mean>0</mean><stddev>0.00637</stddev></noise></y>
            <z><noise type="gaussian"><mean>0</mean><stddev>0.00686</stddev></noise></z>
          </linear_acceleration>
        </imu>
      </sensor>
      
      <!- Barometer: 50 Hz ->
      <sensor name="air_pressure_sensor" type="air_pressure">
        <always_on>1</always_on>
        <update_rate>50</update_rate>
        <air_pressure><pressure>
          <noise type="gaussian"><mean>0</mean><stddev>3</stddev></noise>
        </pressure></air_pressure>
      </sensor>
      
      <!- Magnetometer: 100 Hz ->
      <sensor name="magnetometer_sensor" type="magnetometer">
        <always_on>1</always_on>
        <update_rate>100</update_rate>
        <magnetometer>
          <x><noise type="gaussian"><stddev>0.0001</stddev></noise></x>
          <y><noise type="gaussian"><stddev>0.0001</stddev></noise></y>
          <z><noise type="gaussian"><stddev>0.0001</stddev></noise></z>
        </magnetometer>
      </sensor>
      
      <!- GPS: 30 Hz ->
      <sensor name="navsat_sensor" type="navsat">
        <always_on>1</always_on>
        <update_rate>30</update_rate>
      </sensor>-->
      <sensor name="air_pressure_sensor" type="air_pressure">
        <always_on>1</always_on>
        <update_rate>50</update_rate>
        <air_pressure>
          <pressure>
            <noise type="gaussian">
              <mean>0</mean>
              <stddev>0.01</stddev>
            </noise>
          </pressure>
        </air_pressure>
      </sensor>
      <sensor name="imu_sensor" type="imu">
        <always_on>1</always_on>
        <update_rate>250</update_rate>
        <imu>
          <angular_velocity>
            <x>
              <noise type="gaussian">
                <mean>0</mean>
                <stddev>0.00018665</stddev>
                <dynamic_bias_stddev>3.8785e-05</dynamic_bias_stddev>
                <dynamic_bias_correlation_time>1000</dynamic_bias_correlation_time>
              </noise>
            </x>
            <y>
              <noise type="gaussian">
                <mean>0</mean>
                <stddev>0.00018665</stddev>
                <dynamic_bias_stddev>3.8785e-05</dynamic_bias_stddev>
                <dynamic_bias_correlation_time>1000</dynamic_bias_correlation_time>
              </noise>
            </y>
            <z>
              <noise type="gaussian">
                <mean>0</mean>
                <stddev>0.00018665</stddev>
                <dynamic_bias_stddev>3.8785e-05</dynamic_bias_stddev>
                <dynamic_bias_correlation_time>1000</dynamic_bias_correlation_time>
              </noise>
            </z>
          </angular_velocity>
          <linear_acceleration>
            <x>
              <noise type="gaussian">
                <mean>0</mean>
                <stddev>0.00186</stddev>
                <dynamic_bias_stddev>0.006</dynamic_bias_stddev>
                <dynamic_bias_correlation_time>300</dynamic_bias_correlation_time>
              </noise>
            </x>
            <y>
              <noise type="gaussian">
                <mean>0</mean>
                <stddev>0.00186</stddev>
                <dynamic_bias_stddev>0.006</dynamic_bias_stddev>
                <dynamic_bias_correlation_time>300</dynamic_bias_correlation_time>
              </noise>
            </y>
            <z>
              <noise type="gaussian">
                <mean>0</mean>
                <stddev>0.00186</stddev>
                <dynamic_bias_stddev>0.006</dynamic_bias_stddev>
                <dynamic_bias_correlation_time>300</dynamic_bias_correlation_time>
              </noise>
            </z>
          </linear_acceleration>
        </imu>
      </sensor>
      <sensor name="navsat_sensor" type="navsat">
        <always_on>1</always_on>
        <update_rate>30</update_rate>
      </sensor>

    </link>
    <link name="rotor_0">
      <gravity>true</gravity>
      <self_collide>false</self_collide>
      <velocity_decay />
      <pose>0.2418 -0.2446 0.076024 0 0 0</pose><!--motor poses are fine-->
      <inertial>
        <pose>0 0 0.006 0 0 0</pose>
        <mass>0.049</mass> <!--motor inertias are fine too-->
        <inertia>
          <ixx>0.000097</ixx>
          <ixy>0</ixy>
          <ixz>0</ixz>
          <iyy>0.000097</iyy>
          <iyz>0</iyz>
          <izz>0.000193</izz>
        </inertia>
      </inertial>
      <visual name="rotor_0_visual_motor_bell">
        <pose>0 0 0 0 0 0</pose>
        <geometry>
          <mesh>
            <scale>1 1 1</scale>
            <uri>model://homebrew_base/meshes/Motor_ccw.STL</uri>
          </mesh>
        </geometry>
      </visual>
      <collision name="rotor_0_collision">
        <pose>0 0 0 0 0 0 </pose>
        <geometry>
          <box>
            <size>0.2792307692307692 0.016923076923076923 0.0008461538461538462</size>
          </box>
        </geometry>
        <surface>
          <contact>
            <ode>
              <min_depth>0.001</min_depth>
              <max_vel>0</max_vel>
            </ode>
          </contact>
          <friction>
            <ode />
          </friction>
        </surface>
      </collision>
    </link>
    <joint name="rotor_0_joint" type="revolute">
      <parent>base_link</parent>
      <child>rotor_0</child>
      <axis>
        <xyz>0 0 1</xyz>
        <limit>
          <lower>-1e+16</lower>
          <upper>1e+16</upper>
        </limit>
        <dynamics>
          <spring_reference>0</spring_reference>
          <spring_stiffness>0</spring_stiffness>
        </dynamics>
      </axis>
    </joint>

    <link name="rotor_1">
      <gravity>true</gravity>
      <self_collide>false</self_collide>
      <velocity_decay />
      <pose>-0.2418 0.2446 0.076024 0 0 0</pose>
      <inertial>
        <pose>0 0 0.006 0 0 0</pose>
        <mass>0.049</mass>
        <inertia>
          <ixx>0.000097</ixx>
          <ixy>0</ixy>
          <ixz>0</ixz>
          <iyy>0.000097</iyy>
          <iyz>0</iyz>
          <izz>0.000193</izz>
        </inertia>
      </inertial>
      <visual name="rotor_1_visual_motor_bell">
        <pose>0 0 0 0 0 0</pose>
        <geometry>
          <mesh>
            <scale>1 1 1</scale>
            <uri>model://homebrew_base/meshes/Motor_ccw.STL</uri>
          </mesh>
        </geometry>
      </visual>
      <collision name="rotor_1_collision">
        <pose>0 0 0 0 0 0 </pose>
        <geometry>
          <box>
            <size>0.2792307692307692 0.016923076923076923 0.0008461538461538462</size>
          </box>
        </geometry>
        <surface>
          <contact>
            <ode>
              <min_depth>0.001</min_depth>
              <max_vel>0</max_vel>
            </ode>
          </contact>
          <friction>
            <ode />
          </friction>
        </surface>
      </collision>
    </link>
    <joint name="rotor_1_joint" type="revolute">
      <parent>base_link</parent>
      <child>rotor_1</child>
      <axis>
        <xyz>0 0 1</xyz>
        <limit>
          <lower>-1e+16</lower>
          <upper>1e+16</upper>
        </limit>
        <dynamics>
          <spring_reference>0</spring_reference>
          <spring_stiffness>0</spring_stiffness>
        </dynamics>
      </axis>
    </joint>

    <link name="rotor_2">
      <gravity>true</gravity>
      <self_collide>false</self_collide>
      <velocity_decay />
      <pose>0.2418 0.2446 0.0760238662373196 0 0 0</pose>
      <inertial>
        <pose>0 0 0.006 0 0 0</pose>
        <mass>0.049</mass>
        <inertia>
          <ixx>0.000097</ixx>
          <ixy>0</ixy>
          <ixz>0</ixz>
          <iyy>0.000097</iyy>
          <iyz>0</iyz>
          <izz>0.000193</izz>
        </inertia>
      </inertial>
      <visual name="rotor_2_visual_motor_bell">
        <pose>0 0 0 0 0 0</pose>
        <geometry>
          <mesh>
            <scale>1 1 1</scale>
            <uri>model://homebrew_base/meshes/Motor_cw.STL</uri>
          </mesh>
        </geometry>
      </visual>
      <collision name="rotor_2_collision">
        <pose>0 0 0 0 0 0 </pose>
        <geometry>
          <box>
            <size>0.2792307692307692 0.016923076923076923 0.0008461538461538462</size>
          </box>
        </geometry>
        <surface>
          <contact>
            <ode>
              <min_depth>0.001</min_depth>
              <max_vel>0</max_vel>
            </ode>
          </contact>
          <friction>
            <ode />
          </friction>
        </surface>
      </collision>
    </link>
    <joint name="rotor_2_joint" type="revolute">
      <parent>base_link</parent>
      <child>rotor_2</child>
      <axis>
        <xyz>0 0 1</xyz>
        <limit>
          <lower>-1e+16</lower>
          <upper>1e+16</upper>
        </limit>
        <dynamics>
          <spring_reference>0</spring_reference>
          <spring_stiffness>0</spring_stiffness>
        </dynamics>
      </axis>
    </joint>

    <link name="rotor_3">
      <gravity>true</gravity>
      <self_collide>false</self_collide>
      <velocity_decay />
      <pose>-0.2418 -0.2446 0.0760238662373188 0 0 0</pose>
      <inertial>
        <pose>0 0 0.006 0 0 0</pose>
        <mass>0.049</mass>
        <inertia>
          <ixx>0.000097</ixx>
          <ixy>0</ixy>
          <ixz>0</ixz>
          <iyy>0.000097</iyy>
          <iyz>0</iyz>
          <izz>0.000193</izz>
        </inertia>
      </inertial>
      <!--<inertial>
        <pose>0.000335600549667348 0.000358633714599488 0.00596292184424577 0 0 0</pose>
        <mass>0.0490985538433032</mass>
        <inertia>
          <ixx>1.4699374521077E-05</ixx>
          <ixy>-4.25916993656525E-05</ixy>
          <ixz>-1.13196330399823E-08</ixz>
          <iyy>0.000183642099743052</iyy>
          <iyz>1.74120547169558E-11</iyz>
          <izz>0.000193381715584971</izz>
        </inertia>
      </inertial>-->
      <visual name="rotor_3_visual_motor_bell">
        <pose>0 0 0 0 0 0</pose>
        <geometry>
          <mesh>
            <scale>1 1 1</scale>
            <uri>model://homebrew_base/meshes/Motor_cw.STL</uri>-
          </mesh>
        </geometry>
      </visual>
      <collision name="rotor_3_collision">
        <pose>0 0 0 0 0 0 </pose>
        <geometry>
          <box>
            <size>0.2792307692307692 0.016923076923076923 0.0008461538461538462</size>
          </box>
        </geometry>
        <surface>
          <contact>
            <ode>
              <min_depth>0.001</min_depth>
              <max_vel>0</max_vel>
            </ode>
          </contact>
          <friction>
            <ode />
          </friction>
        </surface>
      </collision>
    </link>
    <joint name="rotor_3_joint" type="revolute">
      <parent>base_link</parent>
      <child>rotor_3</child>
      <axis>
        <xyz>0 0 1</xyz>
        <limit>
          <lower>-1e+16</lower>
          <upper>1e+16</upper>
        </limit>
        <dynamics>
          <spring_reference>0</spring_reference>
          <spring_stiffness>0</spring_stiffness>
        </dynamics>
      </axis>
    </joint>

    <!--<plugin filename="gz-sim-multicopter-motor-model-system" name="gz::sim::systems::MulticopterMotorModel">
        <jointName>rotor_0_joint</jointName>
        <linkName>rotor_0</linkName>
        <turningDirection>ccw</turningDirection>
        <timeConstantUp>0.0125</timeConstantUp>
        <timeConstantDown>0.025</timeConstantDown>
        <maxRotVelocity>1000.0</maxRotVelocity>
        <motorConstant>8.54858e-06</motorConstant>
        <momentConstant>0.016</momentConstant>
        <commandSubTopic>command/motor_speed</commandSubTopic>
        <motorNumber>0</motorNumber>
        <rotorDragCoefficient>8.06428e-05</rotorDragCoefficient>
        <rollingMomentCoefficient>1e-06</rollingMomentCoefficient>
        <rotorVelocitySlowdownSim>10</rotorVelocitySlowdownSim>
        <motorType>velocity</motorType>
      </plugin>
      <plugin filename="gz-sim-multicopter-motor-model-system" name="gz::sim::systems::MulticopterMotorModel">
        <jointName>rotor_1_joint</jointName>
        <linkName>rotor_1</linkName>
        <turningDirection>ccw</turningDirection>
        <timeConstantUp>0.0125</timeConstantUp>
        <timeConstantDown>0.025</timeConstantDown>
        <maxRotVelocity>1000.0</maxRotVelocity>
        <motorConstant>8.54858e-06</motorConstant>
        <momentConstant>0.016</momentConstant>
        <commandSubTopic>command/motor_speed</commandSubTopic>
        <motorNumber>1</motorNumber>
        <rotorDragCoefficient>8.06428e-05</rotorDragCoefficient>
        <rollingMomentCoefficient>1e-06</rollingMomentCoefficient>
        <rotorVelocitySlowdownSim>10</rotorVelocitySlowdownSim>
        <motorType>velocity</motorType>
      </plugin>
      <plugin filename="gz-sim-multicopter-motor-model-system" name="gz::sim::systems::MulticopterMotorModel">
        <jointName>rotor_2_joint</jointName>
        <linkName>rotor_2</linkName>
        <turningDirection>cw</turningDirection>
        <timeConstantUp>0.0125</timeConstantUp>
        <timeConstantDown>0.025</timeConstantDown>
        <maxRotVelocity>1000.0</maxRotVelocity>
        <motorConstant>8.54858e-06</motorConstant>
        <momentConstant>0.016</momentConstant>
        <commandSubTopic>command/motor_speed</commandSubTopic>
        <motorNumber>2</motorNumber>
        <rotorDragCoefficient>8.06428e-05</rotorDragCoefficient>
        <rollingMomentCoefficient>1e-06</rollingMomentCoefficient>
        <rotorVelocitySlowdownSim>10</rotorVelocitySlowdownSim>
        <motorType>velocity</motorType>
      </plugin>
      <plugin filename="gz-sim-multicopter-motor-model-system" name="gz::sim::systems::MulticopterMotorModel">
        <jointName>rotor_3_joint</jointName>
        <linkName>rotor_3</linkName>
        <turningDirection>cw</turningDirection>
        <timeConstantUp>0.0125</timeConstantUp>
        <timeConstantDown>0.025</timeConstantDown>
        <maxRotVelocity>1000.0</maxRotVelocity>
        <motorConstant>8.54858e-06</motorConstant>
        <momentConstant>0.016</momentConstant>
        <commandSubTopic>command/motor_speed</commandSubTopic>
        <motorNumber>3</motorNumber>
        <rotorDragCoefficient>8.06428e-05</rotorDragCoefficient>
        <rollingMomentCoefficient>1e-06</rollingMomentCoefficient>
        <rotorVelocitySlowdownSim>10</rotorVelocitySlowdownSim>
        <motorType>velocity</motorType>
      </plugin>-->
  </model>
</sdf>